<!DOCTYPE html>
<html lang="en">

<head>
    <meta charset="UTF-8">
    <meta http-equiv="X-UA-Compatible" content="IE=edge">
    <meta name="viewport" content="width=device-width, initial-scale=1.0">
    <title>Document</title>
</head>

<body>
    <script>
        // 如果一个promise中有还有多个新建的promise
        // 则后面的.then的第二个回调函数可以不写
        // 直接在最后面加上一个catch，来捕捉到所有的错误

        // 首先来看一个正常版本的
        // 每个then后面都加了第二个回调函数
        let p1 = new Promise((resolve, reject) => {
                // reject('p1 返回失败')
                resolve('p1 成功')
            })
            .then(
                val => {
                    console.log(val)
                    return new Promise((resolve, reject) => {
                        reject('p2 返回失败')
                            // resolve('p2 成功')
                    })
                },
                rea => {
                    console.log(rea)
                }
            )
            .then(
                val => {
                    console.log(val)
                },
                rea => {
                    console.log(rea)
                }
            )


        // 使用catch代替所有then的第二个回调函数
        // 注意这里的catch和原生的不相同
        // 这里catch里面的参数也是一个回调函数
        let p2 = new Promise((resolve, reject) => {
                // reject('p2 返回失败')
                resolve('p2 成功')
            })
            .then(
                val => {
                    console.log(val)
                    return new Promise((resolve, reject) => {
                        reject('p2 then 返回失败')
                            // resolve('p2 then 成功')
                    })
                }
            )
            .then(
                val => {
                    console.log(val)
                }
            )
            .catch((err) => {
                console.log(err)
            })

        // .catch也可以写在中间,放在中间的话,在这个catch之前的错误都可以捕捉
        // 但是catch之后的无法捕捉,所以一般不这么做

        // 如果一个promise中又有.then第二个回调函数
        // 最后又有catch,还是会先走到回调函数中
    </script>
</body>

</html>