<!DOCTYPE html>
<html lang="en">

<head>
    <meta charset="UTF-8">
    <meta http-equiv="X-UA-Compatible" content="IE=edge">
    <meta name="viewport" content="width=device-width, initial-scale=1.0">
    <title>Document</title>
</head>

<body>
    <script>
        // then里面的两个回调函数里可能也会出现错误，比如未定义变量等
        // 希望把这些错误也能被这个then的onRejected捕获到
        // 以便于可以把这个then的错误再返回到下一个then当中
        // 所以在执行then的两个回调函数的时候，也放到try catch里面执行

        // 这种主动设置try catch的目的都是为了有错误的时候让自己的程序来处理
        // 而不是让浏览器来处理
        class Hd {
            static PENDING = "pending"
            static FULFILLED = "fulfilled"
            static REJECTED = "rejected"
            constructor(executor) {
                this.status = Hd.PENDING
                this.value = null
                try {
                    executor(this.resolve.bind(this),
                        this.reject.bind(this))
                } catch (error) {
                    this.reject(error)
                }
            }
            resolve(value) {
                if (this.status == Hd.PENDING) {
                    this.value = value
                    this.status = Hd.FULFILLED
                }
                console.log(this)
            }
            reject(reason) {
                if (this.status == Hd.PENDING) {
                    this.value = reason
                    this.status = Hd.REJECTED
                }
            }

            then(onFulfilled, onRejected) {
                // 判断传进来的参数是不是函数
                if (!(onFulfilled instanceof Function)) {
                    onFulfilled = () => {}
                }
                if (!(onRejected instanceof Function)) {
                    onRejected = () => {}
                }

                // 

                if (this.status == Hd.FULFILLED) {
                    try {
                        onFulfilled(this.value)
                    } catch (error) {
                        onRejected(error)
                    }
                }
                if (this.status == Hd.REJECTED) {
                    try {
                        onRejected(this.value)
                    } catch (error) {
                        onRejected(error) // 待定
                    }
                }
            }
        }

        let promise = new Hd((resolve, reject) => {
                resolve('解决')
                    // reject('拒绝')
            })
            .then((val) => {
                a
                console.log(val)
            }, (reason) => {
                // a
                console.log(reason)
            })

        // 在这里继续暴露出一个问题就是
        // 是执行then的回调函数里的内容，再执行打印houdunren
        // 没有异步的效果
        console.log('houdunren')
    </script>
</body>

</html>